<?xml version="1.0" ?>
<!-- =================================================================================== -->
<!-- |    This document was autogenerated by xacro from /home/lixiang/catkin_
/src/staubli_tx90_support/urdf/tx90.xacro | -->
<!-- |    EDITING THIS FILE BY HAND IS NOT RECOMMENDED                                 | -->
<!-- =================================================================================== -->

<robot name="staubli_tx90">
    <!-- colours based on RAL values supplied by Staubli -->
    <!-- all RAL colours converted using http://www.visual-graphics.de/en/customer-care/ral-colours -->
    <!-- default colours for robots -->
    <!-- links: main serial chain -->
    <!-- <mujoco>
        <compiler 
        meshdir="../tx90/" 
        balanceinertia="true" 
        discardvisual="false" />
    </mujoco> -->
<!--    <link name="world"/>
    <joint name="world-base_link-fixed" type="fixed">
        <parent link="world"/>
        <child link="base_link"/>
        <origin xyz="0.0 0.0 2.0" rpy="0.0 3.141592654 0.0" />
    </joint>
        
    <link name="robot_box">
        <visual>
            <origin rpy="0 0 0" xyz="0 0 0" />
            <geometry>
                <mesh filename="package:/visual/robot_box.stl" />
            </geometry>
            <material name="">
                <color rgba="0.75294 1 0.75294 0.5" />
            </material>
        </visual>
    </link>
    <joint name="joint_box" type="fixed">
        <origin rpy="0 0 0" xyz="0 0 0.47" />
        <parent link="base_link" />
        <child link="robot_box" />
    </joint>-->
    <link name="base_link">
        <visual>
            <origin rpy="0 0 0" xyz="0 0 0" />
            <geometry>
                <mesh filename="package://base_link.stl" />
            </geometry>
            <material name="">
                <color rgba="1.0 0.6078431372549019 0.0 1.0" />
            </material>
        </visual>
        <collision>
            <origin rpy="0 0 0" xyz="0 0 0" />
            <geometry>
                <mesh filename="package://cbase_link.stl" />
            </geometry>
        </collision>
        <inertial>
            <mass value="10.733459" />
            <origin rpy="0.0 0.0 0.0" xyz="0.014288 0.000001 0.122264" />
            <inertia ixx="0.096590" ixy="-0.000005" ixz="-0.003803" iyy="0.087591" iyz="-0.000001" izz="0.081632" />
        </inertial>
    </link>
    <link name="link_1">
        <visual>
            <origin rpy="0 0 0" xyz="0 0 0" />
            <geometry>
                <mesh filename="package://link_1.stl" />
            </geometry>
            <material name="">
                <color rgba="1.0 0.6078431372549019 0.0 1.0" />
            </material>
        </visual>
        <collision>
            <origin rpy="0 0 0" xyz="0 0 0" />
            <geometry>
                <mesh filename="package://clink_1.stl" />
            </geometry>
        </collision>
        <inertial>
            <mass value="16.934564" />
            <origin rpy="0.0 0.0 0.0" xyz="0.019143 0.024764 -0.064596" />
            <inertia ixx="0.222318" ixy="0.016499" ixz="0.023794" iyy="0.208959" iyz="0.031663" izz="0.157081" />
        </inertial>
    </link>
    <link name="link_2">
        <visual>
            <origin rpy="0 0 0" xyz="0 0 0" />
            <geometry>
                <mesh filename="package://link_2.stl" />
            </geometry>
            <material name="">
                <color rgba="1.0 0.6078431372549019 0.0 1.0" />
            </material>
        </visual>
        <collision>
            <origin rpy="0 0 0" xyz="0 0 0" />
            <geometry>
                <mesh filename="package://clink_2.stl" />
            </geometry>
        </collision>
        <inertial>
            <mass value="12.98711" />
            <origin rpy="0.0 0.0 0.0" xyz="-0.000008 0.221181 0.173052" />
            <inertia ixx="0.425299" ixy="0.000005" ixz="-0.000004" iyy="0.452311" iyz="-0.002920" izz="0.054493" />
        </inertial>
    </link>
    <link name="link_3">
        <visual>
            <origin rpy="0 0 0" xyz="0 0 0" />
            <geometry>
                <mesh filename="package://link_3.stl" />
            </geometry>
            <material name="">
                <color rgba="1.0 0.6078431372549019 0.0 1.0" />
            </material>
        </visual>
        <collision>
            <origin rpy="0 0 0" xyz="0 0 0" />
            <geometry>
                <mesh filename="package://clink_3.stl" />
            </geometry>
        </collision>
        <inertial>
            <mass value="7.50151" />
            <origin rpy="0.0 0.0 0.0" xyz="0.000002 0.065008 0.003572" />
            <inertia ixx="0.058902" ixy="0.000000" ixz="0.000001" iyy="0.056884" iyz="-0.003672" izz="0.034271" />
        </inertial>
    </link>
    <link name="link_4">
        <visual>
            <origin rpy="0 0 0" xyz="0 0 0" />
            <geometry>
                <mesh filename="package://link_4.stl" />
            </geometry>
            <material name="">
                <color rgba="1.0 0.6078431372549019 0.0 1.0" />
            </material>
        </visual>
        <collision>
            <origin rpy="0 0 0" xyz="0 0 0" />
            <geometry>
                <mesh filename="package://clink_4.stl" />
            </geometry>
        </collision>
        <inertial>
            <mass value="4.54015" />
            <origin rpy="0.0 0.0 0.0" xyz="-0.002488 0.049988 0.296156" />
            <inertia ixx="0.043246" ixy="0.000003" ixz="-0.000683" iyy="0.038394" iyz="-0.000004" izz="0.014525" />
        </inertial>
    </link>
    <link name="link_5">
        <visual>
            <origin rpy="0 0 0" xyz="0 0 0" />
            <geometry>
                <mesh filename="package://link_5.stl" />
            </geometry>
            <material name="">
                <color rgba="0.5294117647058824 0.5215686274509804 0.5058823529411764 1.0" />
            </material>
        </visual>
        <collision>
            <origin rpy="0 0 0" xyz="0 0 0" />
            <geometry>
                <mesh filename="package://clink_5.stl" />
            </geometry>
        </collision>
        <inertial>
            <mass value="0.56876" />
            <origin rpy="0.0 0.0 0.0" xyz="0.000000 0.049931 0.222823" />
            <inertia ixx="0.001084" ixy="0.000000" ixz="0.000000" iyy="0.001123" iyz="0.000001" izz="0.000383" />
        </inertial>
    </link>
    <link name="link_6">
        <visual>
            <origin rpy="0 0 0" xyz="0 0 0" />
            <geometry>
                <mesh filename="package://link_6.stl" />
            </geometry>
            <material name="">
                <color rgba="0.5294117647058824 0.5215686274509804 0.5058823529411764 1.0" />
            </material>
        </visual>
        <collision>
            <origin rpy="0 0 0" xyz="0 0 0" />
            <geometry>
                <mesh filename="package://clink_6.stl" />
            </geometry>
        </collision>
        <inertial>
            <mass value="0.03098" />
            <origin rpy="0.0 0.0 0.0" xyz="-0.000243 0.050000 -0.006293" />
            <inertia ixx="0.000012" ixy="0.000000" ixz="0.000000" iyy="0.000011" iyz="0.000000" izz="0.000022" />
        </inertial>
    </link>
    <!-- joints: main serial chain -->
    <joint name="joint_1" type="revolute">
        <origin rpy="0 0 0" xyz="0 0 0.478" />
        <parent link="base_link" />
        <child link="link_1" />
        <axis xyz="0 0 1" />
        <!-- from Staubli instruction manual:
      (1) effort limit = 318 Nm if floor mounted
      (2) effort limit = 111 Nm if wall mounted -->
        <limit effort="318.0" lower="-3.141592653589793" upper="3.141592653589793" velocity="6.981317007977318" />
        <dynamics damping="0.0" friction="0.0" />
    </joint>
    <joint name="joint_2" type="revolute">
        <origin rpy="0 0 0" xyz="0.050 0 0" />
        <parent link="link_1" />
        <child link="link_2" />
        <axis xyz="0 1 0" />
        <limit effort="166.0" lower="-2.2689280275926285" upper="2.5743606466916362" velocity="6.981317007977318" />
        <dynamics damping="0.0" friction="0.0" />
    </joint>
    <joint name="joint_3" type="revolute">
        <origin rpy="0 0 0" xyz="0 0.05 0.425" />
        <parent link="link_2" />
        <child link="link_3" />
        <axis xyz="0 1 0" />
        <limit effort="76.0" lower="-2.530727415391778" upper="2.530727415391778" velocity="7.504915783575617" />
        <dynamics damping="0.0" friction="0.0" />
    </joint>
    <joint name="joint_4" type="revolute">
        <origin rpy="0 0 0" xyz="0 0 0" />
        <parent link="link_3" />
        <child link="link_4" />
        <axis xyz="0 0 1" />
        <limit effort="34.0" lower="-4.71238898038469" upper="4.71238898038469" velocity="9.42477796076938" />
        <dynamics damping="0.0" friction="0.0" />
    </joint>
    <joint name="joint_5" type="revolute">
        <origin rpy="0 0 0" xyz="0 0 0.425" />
        <parent link="link_4" />
        <child link="link_5" />
        <axis xyz="0 1 0" />
        <limit effort="29.0" lower="-2.007128639793479" upper="2.443460952792061" velocity="8.290313946973065" />
        <dynamics damping="0.0" friction="0.0" />
    </joint>
    <joint name="joint_6" type="revolute">
        <origin rpy="0 0 0" xyz="0 0 0.100" />
        <parent link="link_5" />
        <child link="link_6" />
        <axis xyz="0 0 1" />
        <limit effort="11.0" lower="-4.71238898038469" upper="4.71238898038469" velocity="13.264502315156905" />
        <dynamics damping="0.0" friction="0.0" />
    </joint>
    <!-- ROS-Industrial 'base' frame: base_link to Staubli World Coordinates transform -->
    <link name="base" />
    <joint name="base_link-base" type="fixed">
        <origin rpy="0 0 0" xyz="0 0 0.478" />
        <parent link="base_link" />
        <child link="base" />
    </joint>
    <!-- ROS-Industrial 'flange' frame: attachment point for EEF models -->
    <link name="flange" />
    <joint name="joint_6-flange" type="fixed">
        <origin rpy="0 -1.5707963267948966 0" xyz="0 0 0" />
        <parent link="link_6" />
        <child link="flange" />
    </joint>
    <!-- ROS-Industrial 'tool0' frame: all-zeros tool frame -->
    <link name="tool0" />
    <joint name="flange-tool0" type="fixed">
        <origin rpy="0 1.5707963267948966 0" xyz="0 0 0" />
        <parent link="flange" />
        <child link="tool0" />
    </joint>
    <!-- ROS-Industrial 'view' frame: view frame -->
    <link name="view" />
    <joint name="joint_6-view" type="fixed">
        <origin rpy="3.141592653589793 0 0" xyz="0 0 1" />
        <parent link="link_6" />
        <child link="view" />
    </joint>
    <!-- eyehand_calibration 'camera_color_frame' : eye on hand -->
    <link name="camera_color_frame" />
    <joint name="joint_6-camera_color_frame" type="fixed">
        <origin rpy="0.0 -0.024434609527920613 -3.141592653589793" xyz="0 0.087304 0.058103" />
        <parent link="link_6" />
        <child link="camera_color_frame" />
    </joint>
  
    <transmission name="trans_joint_1">
        <type>transmission_interface/SimpleTransmission</type>
        <joint name="joint_1">
            <hardwareInterface>hardware_interface/PositionJointInterface</hardwareInterface>
        </joint>
        <actuator name="joint_1_motor">
            <hardwareInterface>hardware_interface/PositionJointInterface</hardwareInterface>
            <mechanicalReduction>1</mechanicalReduction>
        </actuator>
    </transmission>
    <transmission name="trans_joint_2">
        <type>transmission_interface/SimpleTransmission</type>
        <joint name="joint_2">
            <hardwareInterface>hardware_interface/PositionJointInterface</hardwareInterface>
        </joint>
        <actuator name="joint_2_motor">
            <hardwareInterface>hardware_interface/PositionJointInterface</hardwareInterface>
            <mechanicalReduction>1</mechanicalReduction>
        </actuator>
    </transmission>
    <transmission name="trans_joint_3">
        <type>transmission_interface/SimpleTransmission</type>
        <joint name="joint_3">
            <hardwareInterface>hardware_interface/PositionJointInterface</hardwareInterface>
        </joint>
        <actuator name="joint_3_motor">
            <hardwareInterface>hardware_interface/PositionJointInterface</hardwareInterface>
            <mechanicalReduction>1</mechanicalReduction>
        </actuator>
    </transmission>
    <transmission name="trans_joint_4">
        <type>transmission_interface/SimpleTransmission</type>
        <joint name="joint_4">
            <hardwareInterface>hardware_interface/PositionJointInterface</hardwareInterface>
        </joint>
        <actuator name="joint_4_motor">
            <hardwareInterface>hardware_interface/PositionJointInterface</hardwareInterface>
            <mechanicalReduction>1</mechanicalReduction>
        </actuator>
    </transmission>
    <transmission name="trans_joint_5">
        <type>transmission_interface/SimpleTransmission</type>
        <joint name="joint_5">
            <hardwareInterface>hardware_interface/PositionJointInterface</hardwareInterface>
        </joint>
        <actuator name="joint_5_motor">
            <hardwareInterface>hardware_interface/PositionJointInterface</hardwareInterface>
            <mechanicalReduction>1</mechanicalReduction>
        </actuator>
    </transmission>
    <transmission name="trans_joint_6">
        <type>transmission_interface/SimpleTransmission</type>
        <joint name="joint_6">
            <hardwareInterface>hardware_interface/PositionJointInterface</hardwareInterface>
        </joint>
        <actuator name="joint_6_motor">
            <hardwareInterface>hardware_interface/PositionJointInterface</hardwareInterface>
            <mechanicalReduction>1</mechanicalReduction>
        </actuator>
    </transmission>

</robot>

